Workbook

Sheet About
A1: BFPIaE - BAU Fuel Production, Imports, Exports (state, 2024-2050) | B1: Missouri | C1: 46265
A2: State code (derived): | B2: =IFERROR(INDEX(Geography!B:B, MATCH($B$1, Geography!C:C, 0)), "") -> MO
A3: State FIPS: | B3: =IFERROR(INDEX(Geography!A:A, MATCH($B$2, Geography!B:B, 0)), "") -> 29
A4: Census division #: | B4: =IFERROR(INDEX(Geography!D:D, MATCH($B$2, Geography!B:B, 0)), "") -> 4
A5: AEO o&g supply region: | B5: =Region_crosswalk!K3 -> Midcontinent
A6: AEO coal region: | B6: =Region_crosswalk!K4 -> Interior
A7: Workbook: | B7: EPS BFPIaE - state fuel production / imports / exports
A8: Base year (anchor): | B8: 2024
A9: Forecast horizon: | B9: 2050
A10: EPS run seeding demand: | B10: bau-0831
A11: Production growth source: | B11: AEO 2026 (electrnp)
A12: Methodology: | B12: docs/methodology/BFPIaE-growth.md
A13: Design decisions: | B13: outputs/BFPIaE/plan.md
A14: Generator: | B14: outputs/BFPIaE/_build_bfpiae_workbook.py
A15: Built: | B15: 2026-08-31 11:24
A18: PHASE 2: all 21 fuel rows populated where data is available.
A20: FORECAST (2025-2050), v2 design - convergent by construction:
A21: production: 2024 EIA anchor grown on the AEO2026 (electrnp) production index -
A22: regional for crude/NG (supply-region tables 58/59 via Region_crosswalk),
A23: regional for coal (table 65), national for refined products / biofuels / LPG /
A24: hydrogen (tables 11, 19); flat for nuclear, biomass, MSW (no projection
A25: source). EPS treats production as passthrough (FPIEBP priority 3), so its
A26: forecast must come from outside the model.
A27: exports: 2024 anchor scaled by the same AEO production index as production
A28: (exports rise and fall with the state's production), floored by the supply
A29: surplus MAX(..., production - demand) - the same lift the model's
A30: second-priority balancing would apply.
... A82: Per organizational guidance: framed as input for staff review.

Sheet Methodology
A1: BFPIaE - Methodology Summary (v2, built from EPS run bau-0831)
A2: Working draft for staff review. Verify numerical claims against primary sources before external use.
A3: Full methodology: docs/methodology/BFPIaE-growth.md | Decisions: outputs/BFPIaE/plan.md
A5: 1. Scope
A6: 48 contiguous states, 2024-2050, 21 EPS fuels x 3 modes (production / imports / exports), in BTU. Output: the three BFPIaE-* tabs that EPS reads as InputData/fuels/BFPIaE/BFPIaE-{production,imports,exports}.csv. Switch state via About!B1.
A8: 2. The model fact that shapes the design
A9: FPIEBP.csv sets balancing priorities production=3, imports=1, exports=2. EPS therefore passes production through untouched (verified: run output = deployed input for 1008/1008 series) and OVERWRITES imports with MAX(0, C - P + E), where C = BAU Total Energy Use. Two consequences: (a) production must be forecast outside EPS - feeding the model its own production back is circular; (b) input and output agree only if the input already satisfies P + I - E = C.
A11: 3. Construction, per mode
A12: production(2024) = EIA observed anchor (per-fuel Calcs tabs)
A13: production(Y) = production(Y-1) x AEO2026 growth factor [AEO_growth_calcs Sec 2]
A14: demand C(Y) = P + I - E from the EPS run output [Demand_calcs]
A15: exports(Y) = MAX(0, anchor x AEO index, production(Y) - C(Y)) [Sec 3 index plus supply-surplus floor, so exports track the state own production trajectory]
... A44: Treat all outputs as inputs for staff review, not Energy Innovation institutional positions. Open for refinement.

Sheet Sources
A1: BFPIaE - Source Data Provenance
A3: Every embedded raw tab below corresponds to a downloadable EIA / Census file.
A4: All values in Coal_calcs, NG_calcs, etc. trace back to these tabs via SUMIFS / INDEX-MATCH.
A5: Local repo paths under sources/raw/bfpiae/ unless noted.
A6: EIA-API-derived CSVs are regenerated by outputs/BFPIaE/_stage_sources.py (--check re-pulls and diffs against the committed copies).
A7: Tab | B7: Rows | C7: Source file | D7: URL | E7: Vintage | F7: Notes
A8: Geography | B8: 48 | C8: config/geography/state_to_census_division.csv | D8: - | E8: - | F8: 48 contiguous states
A9: Keys | B9: 118 | C9: derived | D9: - | E9: - | F9: BTU conversion factors + state lookup constants
A10: Coal_production_raw | B10: 768 | C10: sources/raw/eia_coal/coalpublic2024.xlsx | D10: https://www.eia.gov/coal/data/browser/ | E10: 2024 | F10: EIA Hist_Coal_Prod 2024, per-mine. Helpers Q,R added for state cleanup + rank.
A11: EIA923_Page1_coal_raw | B11: 595 | C11: EIA923_Schedules_2_3_4_5_M_12_2024_Final.xlsx Page 1 | D11: https://www.eia.gov/electricity/data/eia923/ | E11: 2024 Final | F11: Filtered to coal fuel codes (BIT/SUB/ANT/RC/WC/SC/LIG). Helpers CT,CU added.
A12: Coal_distribution_raw | B12: 1207 | C12: coal_distribution_2024.xlsx (o_24state) | D12: https://www.eia.gov/coal/distribution/annual/ | E12: 2024 | F12: EIA Annual Coal Distribution Report, by quarter x origin x destination.
A13: NG_production_data1_raw | B13: 99 | C13: NG_dry_production_state.xls Data 1 | D13: https://www.eia.gov/dnav/ng/ng_prod_sum_a_EPG0_FPD_mmcf_a.htm | E13: 2024 | F13: EIA Natural Gas Dry Production by state, annual MMcf.
A14: NG_production_data2_raw | B14: 46 | C14: NG_dry_production_state.xls Data 2 | D14: (same as Data 1) | E14: 2024 | F14: Additional states (overflow tab in EIA file).
A15: NG_movements_state_raw | B15: ~1200 | C15: sources/raw/bfpiae/NG_movements_by_state_2019_2024.csv | D15: EIA API v2 route natural-gas/move/ist | E15: 2019-2024 | F15: By-state totals only (duoarea Sxx-Z0S interstate / Sxx-Z00 international); processes MIR/MID/IMI/EEI, MMcf. Replaces the US-national dnav file used through v1, which had no state columns.
A16: Crude_production_raw | B16: 129 | C16: sources/raw/eia_og/PET_CRD_CRPDN_ADC_MBBL_A.xls Data 1 | D16: https://www.eia.gov/dnav/pet/PET_CRD_CRPDN_ADC_MBBLPD_A.htm | E16: 2024 | F16: EIA Field Production of Crude Oil by state, annual thousand barrels. The "Federal Offshore--Gulf of America" column (own series, in no state) anchors the offshore component allocated via GOM_offshore_shares.
A17: GOM_offshore_shares | B17: 4 | C17: BOEM GOMR Active Lease Map (lease counts entered on-tab) | D17: https://www.data.boem.gov/Main/Mapping.aspx | E17: 2025 lease counts | F17: Federal offshore GOM crude allocated to TX/LA/MS/AL by BOEM active lease count (TX 427, MS 2, AL 11, LA remainder of 2206). Same basis as POLICY_State Mapping in OilGasLeasing_Calculations_States_406.xlsx (Jan 2025 Frozen Policy Scenario - States), keeping BAU offshore production consistent with the IiFPfOaGL leasing policy adjustment. Applied to the crude production AND export anchors (Crude_calcs B5/B7). Verify counts against the BOEM source before external use.
A18: Refinery_capacity_raw | B18: 3380 | C18: sources/raw/eia_refinery/refcap25.xlsx | D18: https://www.eia.gov/petroleum/refinerycapacity/ | E18: Jan 1, 2025 | F18: EIA Refinery Capacity by refinery x product x capacity-type. State allocation for petroleum products.
A19: PET_supply_data1_raw | B19: 94 | C19: PET_US_supply_disposition.xls Data 1 | D19: https://www.eia.gov/dnav/pet/pet_sum_snd_d_nus_mbbl_a.htm | E19: 2024 | F19: EIA US Total Petroleum Supply & Disposition, annual thousand barrels.
A20: PET_supply_data5_raw | B20: 94 | C20: PET_US_supply_disposition.xls Data 5 | D20: (same as Data 1) | E20: 2024 | F20: EIA US Finished Petroleum Products supply (gasoline/diesel/jet/heavy/LPG/etc).
A21: Biomass_facilities_raw | B21: 95 | C21: biomass_table1.csv | D21: https://www.eia.gov/biofuels/biomass/ | E21: 2024 (latest) | F21: EIA Monthly Densified Biomass Fuel Report Table 1, facility list by state x annual capacity.
A22: Uranium_production_raw | B22: 29 | C22: uranium_table3.xlsx | D22: https://www.eia.gov/uranium/production/annual/ | E22: 2024 (Jul 2025 release) | F22: EIA Domestic Uranium Production Report Table 3, US national totals (assumed 100% WY).
A23: SEDS_nuclear_raw | B23: 52 | C23: sources/raw/bfpiae/seds_nuclear_nuetb_2024.csv | D23: https://www.eia.gov/state/seds/ (Complete_SEDS_update.csv, MSN NUETB) | E23: 2024P | F23: State nuclear energy consumption (billion BTU). Nuclear imports/exports anchor as the gap vs WY-only production.
A24: H2_capacity_raw | B24: 40 | C24: sources/raw/bfpiae/refinery_h2_capacity_by_state.csv | D24: EIA API series PET.8_NA_8PH_Sxx_6.A | E24: Jan 1, 2025 | F24: Refinery hydrogen production capacity by state (MMCF/D); capacity assumed = production (legacy-workbook assumption). States w/o refineries absent -> 0.
A25: Census_exports_raw | B25: 1458 | C25: sources/raw/census_trade/legacy_census_state_exports_top25_hs6_2017_2020.csv | D25: https://www.census.gov/foreign-trade/statistics/state/data/index.html | E25: 2020 ($M) | F25: Top-25 HS-6 per state by dollar value, extracted verbatim from the legacy eps-texas BFPIaE workbook. Allocates US petroleum exports to states. CAVEAT: top-25 truncation - codes outside a state's top 25 read as zero share. Refresh path: Census intltrade API (needs API key).
A26: Census_imports_raw | B26: 1458 | C26: (as exports) | D26: (as exports) | E26: 2020 ($M) | F26: Kept for QC comparison only - 2025+ imports are the demand residual.
A27: SEDS_biofuel_raw | B27: 102 | C27: sources/raw/bfpiae/seds_biofuel_production_2023.csv | D27: EIA SEDS MSN EMFDB (fuel ethanol) + BDFDB (biodiesel), state production | E27: 2023 | F27: Share basis for splitting US ethanol / biodiesel totals to states. Feedstock-energy basis (billion Btu) - used as a share only, never as a level.
... A50: BFPIaE-imports | B50: 21 | C50: derived in-workbook | D50: - | E50: - | F50: EPS input tab. MAX(0, demand - production + exports) - the model's own first-priority balancing residual.
A52: Known source gaps / refresh paths:
A53: - Census state-trade shares are the 2020 top-25-HS-per-state extract carried over from the legacy workbook: a petroleum code outside a state top-25 list reads as a zero share. Refresh via the Census intltrade API (key-required; none on this machine).
A54: - LPG exports: no state or US series located (EIA propane export series returned nulls), so the anchor is 0 and exports arise only from the supply-surplus floor.
A55: - No public source projects fuel production by state; AEO supply regions are the finest available geography, so states inside a region share one growth shape.
A56: - No regional (PADD) refined-product production projection exists in the AEO tables on hand, so all refined products use one national index (AEO table 11).
A57: - Hydrogen production is proxied by refinery H2 capacity (capacity = production), the legacy workbook assumption; no state H2 production series exists.
A58: - BTU conversion factors on Keys are widely-cited EIA averages; AEO 2026 Suptab 73 would replace them with model-consistent values.
A59: - Region_crosswalk blend weights for split states (TX/NM o&g, KY coal) are approximate; EIA-914 basin splits and the Annual Coal Report east/west KY tonnage would pin them precisely.

Sheet Geography
A1: state_fips | B1: state_abbr | C1: state_name | D1: division_num | E1: division_name
A2: 01 | B2: AL | C2: Alabama | D2: 6 | E2: East South Central
A3: 04 | B3: AZ | C3: Arizona | D3: 9 | E3: Mountain South
A4: 05 | B4: AR | C4: Arkansas | D4: 7 | E4: West South Central
A5: 06 | B5: CA | C5: California | D5: 10 | E5: Pacific
A6: 08 | B6: CO | C6: Colorado | D6: 8 | E6: Mountain North
A7: 09 | B7: CT | C7: Connecticut | D7: 1 | E7: New England
A8: 10 | B8: DE | C8: Delaware | D8: 5 | E8: South Atlantic
A9: 12 | B9: FL | C9: Florida | D9: 5 | E9: South Atlantic
A10: 13 | B10: GA | C10: Georgia | D10: 5 | E10: South Atlantic
A11: 16 | B11: ID | C11: Idaho | D11: 8 | E11: Mountain North
A12: 17 | B12: IL | C12: Illinois | D12: 3 | E12: East North Central
A13: 18 | B13: IN | C13: Indiana | D13: 3 | E13: East North Central
... A49: 56 | B49: WY | C49: Wyoming | D49: 8 | E49: Mountain North

Sheet Keys
A1: category | B1: key | C1: value | D1: description | E1: unit
A2: coal_conversion | B2: hard_coal_mmbtu_per_ton | C2: 20.5 | D2: Hard coal energy content | E2: MMBtu/short ton
A3: coal_conversion | B3: lignite_mmbtu_per_ton | C3: 14 | D3: Lignite energy content | E3: MMBtu/short ton
A4: ng_conversion | B4: ng_btu_per_mcf | C4: 1037 | D4: Natural gas energy content (HHV) | E4: BTU/cubic foot
A5: crude_conversion | B5: crude_mmbtu_per_bbl | C5: 5.8 | D5: Crude oil energy content | E5: MMBtu/barrel
A6: pet_conversion | B6: gasoline_mmbtu_per_bbl | C6: 5.053 | D6: Motor gasoline (RFG+conv) | E6: MMBtu/barrel
A7: pet_conversion | B7: diesel_mmbtu_per_bbl | C7: 5.825 | D7: Distillate fuel oil / diesel | E7: MMBtu/barrel
A8: pet_conversion | B8: jet_mmbtu_per_bbl | C8: 5.67 | D8: Jet fuel / kerosene | E8: MMBtu/barrel
A9: pet_conversion | B9: heavy_oil_mmbtu_per_bbl | C9: 6.287 | D9: Residual (heavy) fuel oil | E9: MMBtu/barrel
A10: pet_conversion | B10: lpg_mmbtu_per_bbl | C10: 3.581 | D10: LPG (propane + butane avg) | E10: MMBtu/barrel
A11: pet_conversion | B11: biofuel_gasoline_mmbtu_per_bbl | C11: 3.539 | D11: Ethanol denatured | E11: MMBtu/barrel
A12: pet_conversion | B12: biofuel_diesel_mmbtu_per_bbl | C12: 5.359 | D12: Biodiesel (B100) | E12: MMBtu/barrel
A13: biomass_conversion | B13: biomass_mmbtu_per_ton | C13: 16 | D13: Wood pellets / densified biomass | E13: MMBtu/short ton
... A16: unit | B16: mcf_to_cf | C16: 1000 | D16: MCF -> cubic feet | E16: -
A17: coal_rank | B17: lignite_state_1 | C17: Texas | D17: Lignite-producing state | E17: -
A18: coal_rank | B18: lignite_state_2 | C18: North Dakota | D18: Lignite-producing state | E18: -
A19: coal_rank | B19: lignite_state_3 | C19: Mississippi | D19: Lignite-producing state | E19: -
A20: coal_rank | B20: lignite_state_4 | C20: Louisiana | D20: Lignite-producing state | E20: -
A21: coal_rank | B21: hard_coal_label | C21: hard_coal | D21: Rank label | E21: -
A22: coal_rank | B22: lignite_label | C22: lignite | D22: Rank label | E22: -
A23: unit | B23: thousand_to_unit | C23: 1000 | D23: Thousand barrels -> barrels; thousand lbs -> lbs | E23: -
A24: unit | B24: mmcf_to_cf | C24: 1000000 | D24: MMcf -> cubic feet | E24: -
A25: unit | B25: gal_per_bbl | C25: 42 | D25: US gallons per barrel | E25: gal/bbl
A26: source_token | B26: anchor_year | C26: 2024 | D26: Base/anchor year matched in raw source tabs | E26: Year
A27: source_token | B27: anchor_year_datewild | C27: 2024-* | D27: Anchor year as an EIA dnav date label (matched with wildcard before the plain numeric year) | E27: -
A28: source_token | B28: wildcard | C28: * | D28: Trailing wildcard appended to a state name when matching raw-tab column headers | E28: -
A29: source_token | B29: state_name_split_token | C29: ( | D29: Separator between state name and parenthetical in coalpublic STATE labels; the helper column keeps everything left of it | E29: -
A30: source_token | B30: eia923_lignite_fuel_code | C30: LIG | D30: EIA-923 Reported Fuel Type Code for lignite; every other coal code is hard coal | E30: -
A31: source_token | B31: duoarea_state_offset | C31: 2 | D31: Start position of the 2-letter state code inside an EIA duoarea code (e.g. SAL -> AL) | E31: char
A32: source_token | B32: duoarea_state_length | C32: 2 | D32: Length of the state code inside an EIA duoarea code | E32: char
A33: source_token | B33: refcap_product_operating_capacity | C33: OPERATING CAPACITY | D33: refcap25 PRODUCT value selecting operating (not idle) capacity rows | E33: -
A34: source_token | B34: refcap_supply_atm_crude | C34: Atmospheric Crude Distillation Capacity (barrels per calendar day) | D34: refcap25 SUPPLY value selecting atmospheric crude distillation capacity | E34: -
A35: source_token | B35: us_total_label | C35: U.S. | D35: Column header prefix for the US-total series in the EIA dnav by-state tabs | E35: -
A36: source_token | B36: crude_oil_label | C36: crude oil | D36: Fuel label used when matching the staged US petroleum export/production tabs | E36: -
A37: source_token | B37: biofuel_gasoline_label | C37: biofuel gasoline | D37: Fuel label in the staged US petroleum export tab | E37: -
A38: source_token | B38: biofuel_diesel_label | C38: biofuel diesel | D38: Fuel label in the staged US petroleum export tab | E38: -
A39: source_token | B39: fuel_ethanol_label | C39: fuel ethanol | D39: Fuel label in the staged US petroleum production tab | E39: -
A40: source_token | B40: us_prod_cat_lpg | C40: lpg | D40: Category in US_pet_production_raw summing propane + n-butane + isobutane (field + refinery). Ethane is deliberately EXCLUDED: the EPS fuel is "LPG propane or butane" and ethane is ~44% of US NGL field production. | E40: -
A41: source_token | B41: us_prod_cat_biofuel_diesel | C41: biofuel diesel | D41: Category in US_pet_production_raw summing biodiesel + renewable diesel net production | E41: -
A42: source_token | B42: seds_biodiesel_label | C42: biodiesel | D42: Fuel label in SEDS_biofuel_raw for the biodiesel rows | E42: -
...

Sheet Region_crosswalk
A1: state_abbr | B1: fuel_group | C1: region_1 | D1: weight_1 | E1: region_2 | F1: weight_2 | G1: notes | H1: helper: match_key | J1: ACTIVE-STATE REGION ASSIGNMENT - resolved from the table at left for About!B1. Read by AEO_growth_calcs section 1.
A2: AL | B2: og | C2: Gulf Coast | D2: 1 | H2: =A2&VLOOKUP("key_separator", Keys!$B:$C, 2, FALSE)&B2 -> AL|og | J2: fuel_group | K2: region 1 | L2: weight 1 | M2: region 2 | N2: weight 2
A3: AZ | B3: og | C3: Rocky Mountain | D3: 1 | H3: =A3&VLOOKUP("key_separator", Keys!$B:$C, 2, FALSE)&B3 -> AZ|og | J3: =VLOOKUP("fuel_group_og", Keys!$B:$C, 2, FALSE) -> og | K3: =IFERROR(INDEX($C$2:$C$97, MATCH(About!$B$2&VLOOKUP("key_separator", Keys!$B:$C, 2, FALSE)&$J3, $H$2:$H$97, 0))&"", "") -> Midcontinent | L3: =IFERROR(--IFERROR(INDEX($D$2:$D$97, MATCH(About!$B$2&VLOOKUP("key_separator", Keys!$B:$C, 2, FALSE)&$J3, $H$2:$H$97, 0)), ""), VLOOKUP("zero_test", Keys!$B:$C, 2, FALSE)) -> 1 | M3: =IFERROR(INDEX($E$2:$E$97, MATCH(About!$B$2&VLOOKUP("key_separator", Keys!$B:$C, 2, FALSE)&$J3, $H$2:$H$97, 0))&"", "") | N3: =IFERROR(--IFERROR(INDEX($F$2:$F$97, MATCH(About!$B$2&VLOOKUP("key_separator", Keys!$B:$C, 2, FALSE)&$J3, $H$2:$H$97, 0)), ""), VLOOKUP("zero_test", Keys!$B:$C, 2, FALSE)) -> 0
A4: AR | B4: og | C4: Midcontinent | D4: 1 | G4: Fayetteville/Arkoma dominant; S-AR Gulf Coast share negligible | H4: =A4&VLOOKUP("key_separator", Keys!$B:$C, 2, FALSE)&B4 -> AR|og | J4: =VLOOKUP("fuel_group_coal", Keys!$B:$C, 2, FALSE) -> coal | K4: =IFERROR(INDEX($C$2:$C$97, MATCH(About!$B$2&VLOOKUP("key_separator", Keys!$B:$C, 2, FALSE)&$J4, $H$2:$H$97, 0))&"", "") -> Interior | L4: =IFERROR(--IFERROR(INDEX($D$2:$D$97, MATCH(About!$B$2&VLOOKUP("key_separator", Keys!$B:$C, 2, FALSE)&$J4, $H$2:$H$97, 0)), ""), VLOOKUP("zero_test", Keys!$B:$C, 2, FALSE)) -> 1 | M4: =IFERROR(INDEX($E$2:$E$97, MATCH(About!$B$2&VLOOKUP("key_separator", Keys!$B:$C, 2, FALSE)&$J4, $H$2:$H$97, 0))&"", "") | N4: =IFERROR(--IFERROR(INDEX($F$2:$F$97, MATCH(About!$B$2&VLOOKUP("key_separator", Keys!$B:$C, 2, FALSE)&$J4, $H$2:$H$97, 0)), ""), VLOOKUP("zero_test", Keys!$B:$C, 2, FALSE)) -> 0
A5: CA | B5: og | C5: West Coast | D5: 1 | H5: =A5&VLOOKUP("key_separator", Keys!$B:$C, 2, FALSE)&B5 -> CA|og
A6: CO | B6: og | C6: Rocky Mountain | D6: 1 | H6: =A6&VLOOKUP("key_separator", Keys!$B:$C, 2, FALSE)&B6 -> CO|og
A7: CT | B7: og | C7: East | D7: 1 | H7: =A7&VLOOKUP("key_separator", Keys!$B:$C, 2, FALSE)&B7 -> CT|og
A8: DE | B8: og | C8: East | D8: 1 | H8: =A8&VLOOKUP("key_separator", Keys!$B:$C, 2, FALSE)&B8 -> DE|og
A9: FL | B9: og | C9: Gulf Coast | D9: 1 | H9: =A9&VLOOKUP("key_separator", Keys!$B:$C, 2, FALSE)&B9 -> FL|og
A10: GA | B10: og | C10: East | D10: 1 | H10: =A10&VLOOKUP("key_separator", Keys!$B:$C, 2, FALSE)&B10 -> GA|og
A11: ID | B11: og | C11: Rocky Mountain | D11: 1 | H11: =A11&VLOOKUP("key_separator", Keys!$B:$C, 2, FALSE)&B11 -> ID|og
A12: IL | B12: og | C12: East | D12: 1 | H12: =A12&VLOOKUP("key_separator", Keys!$B:$C, 2, FALSE)&B12 -> IL|og
A13: IN | B13: og | C13: East | D13: 1 | H13: =A13&VLOOKUP("key_separator", Keys!$B:$C, 2, FALSE)&B13 -> IN|og
A14: IA | B14: og | C14: Midcontinent | D14: 1 | H14: =A14&VLOOKUP("key_separator", Keys!$B:$C, 2, FALSE)&B14 -> IA|og
A15: KS | B15: og | C15: Midcontinent | D15: 1 | H15: =A15&VLOOKUP("key_separator", Keys!$B:$C, 2, FALSE)&B15 -> KS|og
A16: KY | B16: og | C16: East | D16: 1 | H16: =A16&VLOOKUP("key_separator", Keys!$B:$C, 2, FALSE)&B16 -> KY|og
... A29: NJ | B29: og | C29: East | D29: 1 | H29: =A29&VLOOKUP("key_separator", Keys!$B:$C, 2, FALSE)&B29 -> NJ|og
A30: NM | B30: og | C30: Southwest | D30: 0.85 | E30: Rocky Mountain | F30: 0.15 | G30: Permian (SE NM) dominant; San Juan basin (NW) is Rocky Mountain - weight approximates gas-heavy SJ share | H30: =A30&VLOOKUP("key_separator", Keys!$B:$C, 2, FALSE)&B30 -> NM|og
A31: NY | B31: og | C31: East | D31: 1 | H31: =A31&VLOOKUP("key_separator", Keys!$B:$C, 2, FALSE)&B31 -> NY|og
A32: NC | B32: og | C32: East | D32: 1 | H32: =A32&VLOOKUP("key_separator", Keys!$B:$C, 2, FALSE)&B32 -> NC|og
A33: ND | B33: og | C33: Northern Great Plains | D33: 1 | H33: =A33&VLOOKUP("key_separator", Keys!$B:$C, 2, FALSE)&B33 -> ND|og
A34: OH | B34: og | C34: East | D34: 1 | H34: =A34&VLOOKUP("key_separator", Keys!$B:$C, 2, FALSE)&B34 -> OH|og
A35: OK | B35: og | C35: Midcontinent | D35: 1 | H35: =A35&VLOOKUP("key_separator", Keys!$B:$C, 2, FALSE)&B35 -> OK|og
A36: OR | B36: og | C36: West Coast | D36: 1 | H36: =A36&VLOOKUP("key_separator", Keys!$B:$C, 2, FALSE)&B36 -> OR|og
A37: PA | B37: og | C37: East | D37: 1 | H37: =A37&VLOOKUP("key_separator", Keys!$B:$C, 2, FALSE)&B37 -> PA|og
A38: RI | B38: og | C38: East | D38: 1 | H38: =A38&VLOOKUP("key_separator", Keys!$B:$C, 2, FALSE)&B38 -> RI|og
A39: SC | B39: og | C39: East | D39: 1 | H39: =A39&VLOOKUP("key_separator", Keys!$B:$C, 2, FALSE)&B39 -> SC|og
A40: SD | B40: og | C40: Northern Great Plains | D40: 1 | H40: =A40&VLOOKUP("key_separator", Keys!$B:$C, 2, FALSE)&B40 -> SD|og
A41: TN | B41: og | C41: East | D41: 1 | H41: =A41&VLOOKUP("key_separator", Keys!$B:$C, 2, FALSE)&B41 -> TN|og
A42: TX | B42: og | C42: Southwest | D42: 0.65 | E42: Gulf Coast | F42: 0.35 | G42: Permian (SW) vs Eagle Ford/Haynesville-TX/gulf districts (GC); panhandle Midcontinent share folded into SW. Approximate - staff-tunable | H42: =A42&VLOOKUP("key_separator", Keys!$B:$C, 2, FALSE)&B42 -> TX|og
A43: UT | B43: og | C43: Rocky Mountain | D43: 1 | H43: =A43&VLOOKUP("key_separator", Keys!$B:$C, 2, FALSE)&B43 -> UT|og
A44: VT | B44: og | C44: East | D44: 1 | H44: =A44&VLOOKUP("key_separator", Keys!$B:$C, 2, FALSE)&B44 -> VT|og
A45: VA | B45: og | C45: East | D45: 1 | H45: =A45&VLOOKUP("key_separator", Keys!$B:$C, 2, FALSE)&B45 -> VA|og
A46: WA | B46: og | C46: West Coast | D46: 1 | H46: =A46&VLOOKUP("key_separator", Keys!$B:$C, 2, FALSE)&B46 -> WA|og
A47: WV | B47: og | C47: East | D47: 1 | H47: =A47&VLOOKUP("key_separator", Keys!$B:$C, 2, FALSE)&B47 -> WV|og
A48: WI | B48: og | C48: East | D48: 1 | H48: =A48&VLOOKUP("key_separator", Keys!$B:$C, 2, FALSE)&B48 -> WI|og
A49: WY | B49: og | C49: Rocky Mountain | D49: 1 | G49: Powder River + Green River both inside Rocky Mountain-5 per m063 Fig 1-2 | H49: =A49&VLOOKUP("key_separator", Keys!$B:$C, 2, FALSE)&B49 -> WY|og
A50: AL | B50: coal | C50: Appalachia | D50: 1 | H50: =A50&VLOOKUP("key_separator", Keys!$B:$C, 2, FALSE)&B50 -> AL|coal
A51: AZ | B51: coal | C51: West | D51: 1 | H51: =A51&VLOOKUP("key_separator", Keys!$B:$C, 2, FALSE)&B51 -> AZ|coal
A52: AR | B52: coal | C52: Interior | D52: 1 | H52: =A52&VLOOKUP("key_separator", Keys!$B:$C, 2, FALSE)&B52 -> AR|coal
...

Sheet GOM_offshore_shares
A1: GOM_offshore_shares - federal offshore Gulf of Mexico crude allocated to states
A2: Allocation by BOEM active lease count (BOEM GOMR Active Lease Map); Louisiana = remainder. Same basis as POLICY_State Mapping in OilGasLeasing_Calculations_States_406.xlsx (Jan 2025 Frozen Policy Scenario - States), so BAU offshore production and the IiFPfOaGL leasing adjustment are allocated consistently. EIA reports federal offshore GOM crude as its own series - it is in no state's production data.
A4: Active state share of federal offshore GOM (read by Crude_calcs!B9): | B4: =IFERROR(INDEX($C$8:$C$11, MATCH(About!$B$1, $A$8:$A$11, 0)), VLOOKUP("zero_test", Keys!$B:$C, 2, FALSE)) -> 0
A6: State | B6: BOEM active leases (GOM) | C6: share of GOM offshore
A7: Total, Gulf of Mexico region | B7: 2206
A8: Texas | B8: 427 | C8: =B8/$B$7 -> 0.19356301
A9: Mississippi | B9: 2 | C9: =B9/$B$7 -> 0.00090661831
A10: Alabama | B10: 11 | C10: =B10/$B$7 -> 0.0049864007
A11: Louisiana | B11: =B7-SUM(B8:B10) -> 1766 | C11: =B11/$B$7 -> 0.80054397
A12: check: state leases sum to total / shares sum to 1 | B12: =SUM(B8:B11) -> 2206 | C12: =SUM(C8:C11) -> 1
A14: Scope: crude oil only. Federal offshore GOM natural gas (~593 Bcf in 2024, vs LA state series ~3,598 Bcf) is NOT yet allocated - flagged follow-up. Cook Inlet (AK) offshore is out of scope (AK not in the 48-state build).

Sheet Coal_production_raw
A1: Historical Coal Production Data: 2024
A2: Source: The U.S. Energy Information Administration (EIA) and the U.S. Mine Safety and Health Administration
A4: Year | B4: MSHA ID | C4: Mine Name | D4: Mine State | E4: Mine County | F4: Mine Status | G4: Mine Type | H4: Company Type | I4: Operation Type | J4: Operating Company | K4: Operating Company Address | L4: Union Code | M4: Coal Supply Region | N4: Production (short tons) | O4: Average Employees | P4: Labor Hours | Q4: helper: state_name_clean | R4: helper: rank
A5: 2024 | B5: 103441 | C5: Marvel Mine | D5: Alabama | E5: Bibb | F5: Permanently abandoned | G5: Surface | H5: Independent Producer Operator | I5: Mine only | J5: Camellia Met Mining, Llc | K5: 1615 Kent Dairy Road, Alabaster, AL 35007 | M5: Appalachia Southern | N5: 34001 | O5: 3 | P5: 5192 | Q5: =IFERROR(LEFT(D5, FIND(VLOOKUP("state_name_split_token", Keys!$B:$C, 2, FALSE), D5)-1), D5) -> Alabama | R5: =IF(OR(Q5=VLOOKUP("lignite_state_1", Keys!$B:$C, 2, FALSE),Q5=VLOOKUP("lignite_state_2", Keys!$B:$C, 2, FALSE),Q5=VLOOKUP("lignite_state_3", Keys!$B:$C, 2, FALSE),Q5=VLOOKUP("lignite_state_4", Keys!$B:$C, 2, FALSE)),VLOOKUP("lignite_label", Keys!$B:$C, 2, FALSE),VLOOKUP("hard_coal_label", Keys!$B:$C, 2, FALSE)) -> hard_coal
A6: 2024 | B6: 103540 | C6: Dodge Mine | D6: Alabama | E6: Cullman | F6: Active | G6: Surface | H6: Independent Producer Operator | I6: Preparation Plant | J6: Southern Mineral Resources Llc | K6: 1915 County Road 8, Hanceville, AL 35077 | M6: Appalachia Southern | N6: 0 | O6: 7 | P6: 15793 | Q6: =IFERROR(LEFT(D6, FIND(VLOOKUP("state_name_split_token", Keys!$B:$C, 2, FALSE), D6)-1), D6) -> Alabama | R6: =IF(OR(Q6=VLOOKUP("lignite_state_1", Keys!$B:$C, 2, FALSE),Q6=VLOOKUP("lignite_state_2", Keys!$B:$C, 2, FALSE),Q6=VLOOKUP("lignite_state_3", Keys!$B:$C, 2, FALSE),Q6=VLOOKUP("lignite_state_4", Keys!$B:$C, 2, FALSE)),VLOOKUP("lignite_label", Keys!$B:$C, 2, FALSE),VLOOKUP("hard_coal_label", Keys!$B:$C, 2, FALSE)) -> hard_coal
A7: 2024 | B7: 100329 | C7: Oak Grove Preparation Plant | D7: Alabama | E7: Jefferson | F7: Active | G7: Underground | H7: Operating Subsidiary | I7: Preparation Plant | J7: Crimson Oak Grove Resources Ll | K7: 8360 Taylors Ferry Rd, Hueytown, AL 35023 | L7: United Mine Workers Of America | M7: Appalachia Southern | N7: 0 | O7: 55 | P7: 136552 | Q7: =IFERROR(LEFT(D7, FIND(VLOOKUP("state_name_split_token", Keys!$B:$C, 2, FALSE), D7)-1), D7) -> Alabama | R7: =IF(OR(Q7=VLOOKUP("lignite_state_1", Keys!$B:$C, 2, FALSE),Q7=VLOOKUP("lignite_state_2", Keys!$B:$C, 2, FALSE),Q7=VLOOKUP("lignite_state_3", Keys!$B:$C, 2, FALSE),Q7=VLOOKUP("lignite_state_4", Keys!$B:$C, 2, FALSE)),VLOOKUP("lignite_label", Keys!$B:$C, 2, FALSE),VLOOKUP("hard_coal_label", Keys!$B:$C, 2, FALSE)) -> hard_coal
A8: 2024 | B8: 100851 | C8: Oak Grove Mine | D8: Alabama | E8: Jefferson | F8: Active | G8: Underground | H8: Operating Subsidiary | I8: Mine only | J8: Crimson Oak Grove Resources Ll | K8: 8800 Oak Grove Mine Road, Adger, AL 35006 | L8: United Mine Workers Of America | M8: Appalachia Southern | N8: 2806000 | O8: 490 | P8: 1242668 | Q8: =IFERROR(LEFT(D8, FIND(VLOOKUP("state_name_split_token", Keys!$B:$C, 2, FALSE), D8)-1), D8) -> Alabama | R8: =IF(OR(Q8=VLOOKUP("lignite_state_1", Keys!$B:$C, 2, FALSE),Q8=VLOOKUP("lignite_state_2", Keys!$B:$C, 2, FALSE),Q8=VLOOKUP("lignite_state_3", Keys!$B:$C, 2, FALSE),Q8=VLOOKUP("lignite_state_4", Keys!$B:$C, 2, FALSE)),VLOOKUP("lignite_label", Keys!$B:$C, 2, FALSE),VLOOKUP("hard_coal_label", Keys!$B:$C, 2, FALSE)) -> hard_coal
A9: 2024 | B9: 101401 | C9: No 7 Mine | D9: Alabama | E9: Jefferson | F9: Active | G9: Underground | H9: Independent Producer Operator | I9: Mine and Preparation Plant | J9: Warrior Met Coal Mining, Llc | K9: P.O. Box 133, Brookwood, AL 35444 | L9: United Mine Workers Of America | M9: Appalachia Southern | N9: 5269294 | O9: 646 | P9: 1875571 | Q9: =IFERROR(LEFT(D9, FIND(VLOOKUP("state_name_split_token", Keys!$B:$C, 2, FALSE), D9)-1), D9) -> Alabama | R9: =IF(OR(Q9=VLOOKUP("lignite_state_1", Keys!$B:$C, 2, FALSE),Q9=VLOOKUP("lignite_state_2", Keys!$B:$C, 2, FALSE),Q9=VLOOKUP("lignite_state_3", Keys!$B:$C, 2, FALSE),Q9=VLOOKUP("lignite_state_4", Keys!$B:$C, 2, FALSE)),VLOOKUP("lignite_label", Keys!$B:$C, 2, FALSE),VLOOKUP("hard_coal_label", Keys!$B:$C, 2, FALSE)) -> hard_coal
A10: 2024 | B10: 103182 | C10: Fishtrap | D10: Alabama | E10: Jefferson | F10: Active | G10: Surface | H10: Independent Producer Operator | I10: Mine only | J10: Highland Energy, Inc. | K10: 7802 Highway 78, Cordova, AL 35550 | M10: Appalachia Southern | N10: 12131 | O10: 10 | P10: 20616 | Q10: =IFERROR(LEFT(D10, FIND(VLOOKUP("state_name_split_token", Keys!$B:$C, 2, FALSE), D10)-1), D10) -> Alabama | R10: =IF(OR(Q10=VLOOKUP("lignite_state_1", Keys!$B:$C, 2, FALSE),Q10=VLOOKUP("lignite_state_2", Keys!$B:$C, 2, FALSE),Q10=VLOOKUP("lignite_state_3", Keys!$B:$C, 2, FALSE),Q10=VLOOKUP("lignite_state_4", Keys!$B:$C, 2, FALSE)),VLOOKUP("lignite_label", Keys!$B:$C, 2, FALSE),VLOOKUP("hard_coal_label", Keys!$B:$C, 2, FALSE)) -> hard_coal
A11: 2024 | B11: 103419 | C11: Maxine-Pratt Mine | D11: Alabama | E11: Jefferson | F11: Active | G11: Underground | H11: Independent Producer Operator | I11: Mine only | J11: Prospect Mining & Development | K11: 2002 Second Ave. S., Jasper, AL 35501 | M11: Appalachia Southern | N11: 102539 | O11: 35 | P11: 90127 | Q11: =IFERROR(LEFT(D11, FIND(VLOOKUP("state_name_split_token", Keys!$B:$C, 2, FALSE), D11)-1), D11) -> Alabama | R11: =IF(OR(Q11=VLOOKUP("lignite_state_1", Keys!$B:$C, 2, FALSE),Q11=VLOOKUP("lignite_state_2", Keys!$B:$C, 2, FALSE),Q11=VLOOKUP("lignite_state_3", Keys!$B:$C, 2, FALSE),Q11=VLOOKUP("lignite_state_4", Keys!$B:$C, 2, FALSE)),VLOOKUP("lignite_label", Keys!$B:$C, 2, FALSE),VLOOKUP("hard_coal_label", Keys!$B:$C, 2, FALSE)) -> hard_coal
A12: 2024 | B12: 103523 | C12: Shannon Mine No. 3 | D12: Alabama | E12: Jefferson | F12: Active | G12: Surface | H12: Independent Producer Operator | I12: Mine only | J12: Rjr Mining Company, Inc. | K12: 7202 Highway 78, Cordova, AL 35550 | M12: Appalachia Southern | N12: 234625 | O12: 66 | P12: 151432 | Q12: =IFERROR(LEFT(D12, FIND(VLOOKUP("state_name_split_token", Keys!$B:$C, 2, FALSE), D12)-1), D12) -> Alabama | R12: =IF(OR(Q12=VLOOKUP("lignite_state_1", Keys!$B:$C, 2, FALSE),Q12=VLOOKUP("lignite_state_2", Keys!$B:$C, 2, FALSE),Q12=VLOOKUP("lignite_state_3", Keys!$B:$C, 2, FALSE),Q12=VLOOKUP("lignite_state_4", Keys!$B:$C, 2, FALSE)),VLOOKUP("lignite_label", Keys!$B:$C, 2, FALSE),VLOOKUP("hard_coal_label", Keys!$B:$C, 2, FALSE)) -> hard_coal
A13: 2024 | B13: 102976 | C13: Piney Woods Preparation Plant | D13: Alabama | E13: Shelby | F13: Active | G13: Surface | H13: Independent Producer Operator | I13: Preparation Plant | J13: Camellia Met Mining, Llc | K13: 3400 County Road 260, Alabaster, AL 35114 | M13: Appalachia Southern | N13: 0 | O13: 3 | P13: 6240 | Q13: =IFERROR(LEFT(D13, FIND(VLOOKUP("state_name_split_token", Keys!$B:$C, 2, FALSE), D13)-1), D13) -> Alabama | R13: =IF(OR(Q13=VLOOKUP("lignite_state_1", Keys!$B:$C, 2, FALSE),Q13=VLOOKUP("lignite_state_2", Keys!$B:$C, 2, FALSE),Q13=VLOOKUP("lignite_state_3", Keys!$B:$C, 2, FALSE),Q13=VLOOKUP("lignite_state_4", Keys!$B:$C, 2, FALSE)),VLOOKUP("lignite_label", Keys!$B:$C, 2, FALSE),VLOOKUP("hard_coal_label", Keys!$B:$C, 2, FALSE)) -> hard_coal
A14: 2024 | B14: 103217 | C14: Coke Mine No 1 | D14: Alabama | E14: Shelby | F14: Active, men working, not producing | G14: Surface | H14: Independent Producer Operator | I14: Mine only | J14: Alabama Met Coal Resources Cor | K14: P.O. Box 217, St. Clairsvil, OH 43950 | M14: Appalachia Southern | N14: 1457 | O14: 4 | P14: 4965 | Q14: =IFERROR(LEFT(D14, FIND(VLOOKUP("state_name_split_token", Keys!$B:$C, 2, FALSE), D14)-1), D14) -> Alabama | R14: =IF(OR(Q14=VLOOKUP("lignite_state_1", Keys!$B:$C, 2, FALSE),Q14=VLOOKUP("lignite_state_2", Keys!$B:$C, 2, FALSE),Q14=VLOOKUP("lignite_state_3", Keys!$B:$C, 2, FALSE),Q14=VLOOKUP("lignite_state_4", Keys!$B:$C, 2, FALSE)),VLOOKUP("lignite_label", Keys!$B:$C, 2, FALSE),VLOOKUP("hard_coal_label", Keys!$B:$C, 2, FALSE)) -> hard_coal
A15: 2024 | B15: 103380 | C15: Calera | D15: Alabama | E15: Shelby | F15: Active | G15: Surface | H15: Independent Producer Operator | I15: Preparation Plant | J15: Conrad Yelvington Distributors | K15: 4636 Scarborough Dr, Lutz, FL 33559 | M15: Appalachia Southern | N15: 0 | O15: 1 | P15: 1251 | Q15: =IFERROR(LEFT(D15, FIND(VLOOKUP("state_name_split_token", Keys!$B:$C, 2, FALSE), D15)-1), D15) -> Alabama | R15: =IF(OR(Q15=VLOOKUP("lignite_state_1", Keys!$B:$C, 2, FALSE),Q15=VLOOKUP("lignite_state_2", Keys!$B:$C, 2, FALSE),Q15=VLOOKUP("lignite_state_3", Keys!$B:$C, 2, FALSE),Q15=VLOOKUP("lignite_state_4", Keys!$B:$C, 2, FALSE)),VLOOKUP("lignite_label", Keys!$B:$C, 2, FALSE),VLOOKUP("hard_coal_label", Keys!$B:$C, 2, FALSE)) -> hard_coal
A16: 2024 | B16: 103380 | C16: Calera | D16: Alabama | E16: Shelby | F16: Active | G16: Underground | H16: Independent Producer Operator | I16: Preparation Plant | J16: Conrad Yelvington Distributors | K16: 4636 Scarborough Dr, Lutz, FL 33559 | M16: Appalachia Southern | N16: 0 | O16: 11 | P16: 23779 | Q16: =IFERROR(LEFT(D16, FIND(VLOOKUP("state_name_split_token", Keys!$B:$C, 2, FALSE), D16)-1), D16) -> Alabama | R16: =IF(OR(Q16=VLOOKUP("lignite_state_1", Keys!$B:$C, 2, FALSE),Q16=VLOOKUP("lignite_state_2", Keys!$B:$C, 2, FALSE),Q16=VLOOKUP("lignite_state_3", Keys!$B:$C, 2, FALSE),Q16=VLOOKUP("lignite_state_4", Keys!$B:$C, 2, FALSE)),VLOOKUP("lignite_label", Keys!$B:$C, 2, FALSE),VLOOKUP("hard_coal_label", Keys!$B:$C, 2, FALSE)) -> hard_coal
A17: 2024 | B17: 101247 | C17: No 4 Mine | D17: Alabama | E17: Tuscaloosa | F17: Active | G17: Underground | H17: Independent Producer Operator | I17: Mine and Preparation Plant | J17: Warrior Met Coal Mining, Llc | K17: 14730 Lock 17 Rd, Brookwood, AL 35444 | L17: United Mine Workers Of America | M17: Appalachia Southern | N17: 2769238 | O17: 428 | P17: 1170251 | Q17: =IFERROR(LEFT(D17, FIND(VLOOKUP("state_name_split_token", Keys!$B:$C, 2, FALSE), D17)-1), D17) -> Alabama | R17: =IF(OR(Q17=VLOOKUP("lignite_state_1", Keys!$B:$C, 2, FALSE),Q17=VLOOKUP("lignite_state_2", Keys!$B:$C, 2, FALSE),Q17=VLOOKUP("lignite_state_3", Keys!$B:$C, 2, FALSE),Q17=VLOOKUP("lignite_state_4", Keys!$B:$C, 2, FALSE)),VLOOKUP("lignite_label", Keys!$B:$C, 2, FALSE),VLOOKUP("hard_coal_label", Keys!$B:$C, 2, FALSE)) -> hard_coal
A18: 2024 | B18: 103436 | C18: Swann's Crossing | D18: Alabama | E18: Tuscaloosa | F18: Active | G18: Surface | H18: Independent Producer Operator | I18: Mine only | J18: Southland Resources, Inc. | K18: P.O. Box 770, Cottondale, AL 35453 | M18: Appalachia Southern | N18: 270802 | O18: 80 | P18: 195467 | Q18: =IFERROR(LEFT(D18, FIND(VLOOKUP("state_name_split_token", Keys!$B:$C, 2, FALSE), D18)-1), D18) -> Alabama | R18: =IF(OR(Q18=VLOOKUP("lignite_state_1", Keys!$B:$C, 2, FALSE),Q18=VLOOKUP("lignite_state_2", Keys!$B:$C, 2, FALSE),Q18=VLOOKUP("lignite_state_3", Keys!$B:$C, 2, FALSE),Q18=VLOOKUP("lignite_state_4", Keys!$B:$C, 2, FALSE)),VLOOKUP("lignite_label", Keys!$B:$C, 2, FALSE),VLOOKUP("hard_coal_label", Keys!$B:$C, 2, FALSE)) -> hard_coal
A19: 2024 | B19: 103448 | C19: Blue Creek Mine No. 1 | D19: Alabama | E19: Tuscaloosa | F19: Active | G19: Underground | H19: Independent Producer Operator | I19: Mine only | J19: Warrior Met Coal Bc, Llc | K19: P.O. Box 133, Brookwood, AL 35444 | M19: Appalachia Southern | N19: 208760 | O19: 160 | P19: 67001 | Q19: =IFERROR(LEFT(D19, FIND(VLOOKUP("state_name_split_token", Keys!$B:$C, 2, FALSE), D19)-1), D19) -> Alabama | R19: =IF(OR(Q19=VLOOKUP("lignite_state_1", Keys!$B:$C, 2, FALSE),Q19=VLOOKUP("lignite_state_2", Keys!$B:$C, 2, FALSE),Q19=VLOOKUP("lignite_state_3", Keys!$B:$C, 2, FALSE),Q19=VLOOKUP("lignite_state_4", Keys!$B:$C, 2, FALSE)),VLOOKUP("lignite_label", Keys!$B:$C, 2, FALSE),VLOOKUP("hard_coal_label", Keys!$B:$C, 2, FALSE)) -> hard_coal
A20: 2024 | B20: 103548 | C20: Camp Cherry Austin | D20: Alabama | E20: Tuscaloosa | F20: Active | G20: Surface | H20: Independent Producer Operator | I20: Mine only | J20: Southland Resources, Inc. | K20: P.O. Box 770, Cottondale, AL 35453 | M20: Appalachia Southern | N20: 103949 | O20: 8 | P20: 23512 | Q20: =IFERROR(LEFT(D20, FIND(VLOOKUP("state_name_split_token", Keys!$B:$C, 2, FALSE), D20)-1), D20) -> Alabama | R20: =IF(OR(Q20=VLOOKUP("lignite_state_1", Keys!$B:$C, 2, FALSE),Q20=VLOOKUP("lignite_state_2", Keys!$B:$C, 2, FALSE),Q20=VLOOKUP("lignite_state_3", Keys!$B:$C, 2, FALSE),Q20=VLOOKUP("lignite_state_4", Keys!$B:$C, 2, FALSE)),VLOOKUP("lignite_label", Keys!$B:$C, 2, FALSE),VLOOKUP("hard_coal_label", Keys!$B:$C, 2, FALSE)) -> hard_coal
A21: 2024 | B21: 103556 | C21: Eaton Resources Pit 1 | D21: Alabama | E21: Tuscaloosa | F21: Active | G21: Surface | H21: Independent Producer Operator | I21: Mine only | J21: Eaton Resources Llc | K21: 16241 B&l Road, Cottondale, AL 35453 | M21: Appalachia Southern | N21: 58531 | O21: 15 | P21: 30662 | Q21: =IFERROR(LEFT(D21, FIND(VLOOKUP("state_name_split_token", Keys!$B:$C, 2, FALSE), D21)-1), D21) -> Alabama | R21: =IF(OR(Q21=VLOOKUP("lignite_state_1", Keys!$B:$C, 2, FALSE),Q21=VLOOKUP("lignite_state_2", Keys!$B:$C, 2, FALSE),Q21=VLOOKUP("lignite_state_3", Keys!$B:$C, 2, FALSE),Q21=VLOOKUP("lignite_state_4", Keys!$B:$C, 2, FALSE)),VLOOKUP("lignite_label", Keys!$B:$C, 2, FALSE),VLOOKUP("hard_coal_label", Keys!$B:$C, 2, FALSE)) -> hard_coal
A22: 2024 | B22: 103559 | C22: Rockcastle Mine | D22: Alabama | E22: Tuscaloosa | F22: Active | G22: Surface | H22: Independent Producer Operator | I22: Mine only | J22: Cahaba Resouces, Llc | K22: P.O. Box 122, Vance, AL 35490 | M22: Appalachia Southern | N22: 72209 | O22: 18 | P22: 38747 | Q22: =IFERROR(LEFT(D22, FIND(VLOOKUP("state_name_split_token", Keys!$B:$C, 2, FALSE), D22)-1), D22) -> Alabama | R22: =IF(OR(Q22=VLOOKUP("lignite_state_1", Keys!$B:$C, 2, FALSE),Q22=VLOOKUP("lignite_state_2", Keys!$B:$C, 2, FALSE),Q22=VLOOKUP("lignite_state_3", Keys!$B:$C, 2, FALSE),Q22=VLOOKUP("lignite_state_4", Keys!$B:$C, 2, FALSE)),VLOOKUP("lignite_label", Keys!$B:$C, 2, FALSE),VLOOKUP("hard_coal_label", Keys!$B:$C, 2, FALSE)) -> hard_coal
A23: 2024 | B23: 103577 | C23: Kellerman | D23: Alabama | E23: Tuscaloosa | F23: Active | G23: Underground | H23: Independent Producer Operator | I23: Mine only | J23: Alaco Llc | K23: 414 Elder Grove Dr., Ewing, VA 24248 | M23: Appalachia Southern | N23: 92066 | O23: 23 | P23: 46833 | Q23: =IFERROR(LEFT(D23, FIND(VLOOKUP("state_name_split_token", Keys!$B:$C, 2, FALSE), D23)-1), D23) -> Alabama | R23: =IF(OR(Q23=VLOOKUP("lignite_state_1", Keys!$B:$C, 2, FALSE),Q23=VLOOKUP("lignite_state_2", Keys!$B:$C, 2, FALSE),Q23=VLOOKUP("lignite_state_3", Keys!$B:$C, 2, FALSE),Q23=VLOOKUP("lignite_state_4", Keys!$B:$C, 2, FALSE)),VLOOKUP("lignite_label", Keys!$B:$C, 2, FALSE),VLOOKUP("hard_coal_label", Keys!$B:$C, 2, FALSE)) -> hard_coal
A24: 2024 | B24: 102901 | C24: Shoal Creek Mine | D24: Alabama | E24: Walker | F24: Active | G24: Underground | H24: Operating Subsidiary | I24: Mine and Preparation Plant | J24: Peabody Southeast Mining, Llc | K24: P.O. Box 327, Oakman, AL 35579 | L24: United Mine Workers Of America | M24: Appalachia Southern | N24: 2102725 | O24: 393 | P24: 1136153 | Q24: =IFERROR(LEFT(D24, FIND(VLOOKUP("state_name_split_token", Keys!$B:$C, 2, FALSE), D24)-1), D24) -> Alabama | R24: =IF(OR(Q24=VLOOKUP("lignite_state_1", Keys!$B:$C, 2, FALSE),Q24=VLOOKUP("lignite_state_2", Keys!$B:$C, 2, FALSE),Q24=VLOOKUP("lignite_state_3", Keys!$B:$C, 2, FALSE),Q24=VLOOKUP("lignite_state_4", Keys!$B:$C, 2, FALSE)),VLOOKUP("lignite_label", Keys!$B:$C, 2, FALSE),VLOOKUP("hard_coal_label", Keys!$B:$C, 2, FALSE)) -> hard_coal
A25: 2024 | B25: 103155 | C25: Corinth Prep Plant | D25: Alabama | E25: Walker | F25: Active | G25: Underground | H25: Independent Producer Operator | I25: Preparation Plant | J25: Prospect Mining & Development | K25: 1799 Elliott Blvd, Jasper, AL 35501 | M25: Appalachia Southern | N25: 0 | O25: 12 | P25: 31140 | Q25: =IFERROR(LEFT(D25, FIND(VLOOKUP("state_name_split_token", Keys!$B:$C, 2, FALSE), D25)-1), D25) -> Alabama | R25: =IF(OR(Q25=VLOOKUP("lignite_state_1", Keys!$B:$C, 2, FALSE),Q25=VLOOKUP("lignite_state_2", Keys!$B:$C, 2, FALSE),Q25=VLOOKUP("lignite_state_3", Keys!$B:$C, 2, FALSE),Q25=VLOOKUP("lignite_state_4", Keys!$B:$C, 2, FALSE)),VLOOKUP("lignite_label", Keys!$B:$C, 2, FALSE),VLOOKUP("hard_coal_label", Keys!$B:$C, 2, FALSE)) -> hard_coal
A26: 2024 | B26: 103389 | C26: Carbon Hill Mine | D26: Alabama | E26: Walker | F26: Active | G26: Underground | H26: Independent Producer Operator | I26: Mine only | J26: Clas Coal Company Inc. | K26: P.O. Box 400, Carbon Hill, AL 35549 | M26: Appalachia Southern | N26: 120633 | O26: 30 | P26: 68118 | Q26: =IFERROR(LEFT(D26, FIND(VLOOKUP("state_name_split_token", Keys!$B:$C, 2, FALSE), D26)-1), D26) -> Alabama | R26: =IF(OR(Q26=VLOOKUP("lignite_state_1", Keys!$B:$C, 2, FALSE),Q26=VLOOKUP("lignite_state_2", Keys!$B:$C, 2, FALSE),Q26=VLOOKUP("lignite_state_3", Keys!$B:$C, 2, FALSE),Q26=VLOOKUP("lignite_state_4", Keys!$B:$C, 2, FALSE)),VLOOKUP("lignite_label", Keys!$B:$C, 2, FALSE),VLOOKUP("hard_coal_label", Keys!$B:$C, 2, FALSE)) -> hard_coal
A27: 2024 | B27: 103426 | C27: Carbon Hill Prep Plant | D27: Alabama | E27: Walker | F27: Active | G27: Underground | H27: Independent Producer Operator | I27: Preparation Plant | J27: Prospect Mining & Development | K27: 218 Highway 195, Jasper, AL 35503 | M27: Appalachia Southern | N27: 0 | O27: 9 | P27: 23578 | Q27: =IFERROR(LEFT(D27, FIND(VLOOKUP("state_name_split_token", Keys!$B:$C, 2, FALSE), D27)-1), D27) -> Alabama | R27: =IF(OR(Q27=VLOOKUP("lignite_state_1", Keys!$B:$C, 2, FALSE),Q27=VLOOKUP("lignite_state_2", Keys!$B:$C, 2, FALSE),Q27=VLOOKUP("lignite_state_3", Keys!$B:$C, 2, FALSE),Q27=VLOOKUP("lignite_state_4", Keys!$B:$C, 2, FALSE)),VLOOKUP("lignite_label", Keys!$B:$C, 2, FALSE),VLOOKUP("hard_coal_label", Keys!$B:$C, 2, FALSE)) -> hard_coal
A28: 2024 | B28: 103456 | C28: No. 5 Mine | D28: Alabama | E28: Walker | F28: Active | G28: Surface | H28: Independent Producer Operator | I28: Mine only | J28: Highland Energy, Inc | K28: 7802 Highway 78, Cordova, AL 35550 | M28: Appalachia Southern | N28: 120122 | O28: 16 | P28: 41374 | Q28: =IFERROR(LEFT(D28, FIND(VLOOKUP("state_name_split_token", Keys!$B:$C, 2, FALSE), D28)-1), D28) -> Alabama | R28: =IF(OR(Q28=VLOOKUP("lignite_state_1", Keys!$B:$C, 2, FALSE),Q28=VLOOKUP("lignite_state_2", Keys!$B:$C, 2, FALSE),Q28=VLOOKUP("lignite_state_3", Keys!$B:$C, 2, FALSE),Q28=VLOOKUP("lignite_state_4", Keys!$B:$C, 2, FALSE)),VLOOKUP("lignite_label", Keys!$B:$C, 2, FALSE),VLOOKUP("hard_coal_label", Keys!$B:$C, 2, FALSE)) -> hard_coal
A29: 2024 | B29: 103497 | C29: Gooden Creek Ii | D29: Alabama | E29: Walker | F29: Active | G29: Surface | H29: Independent Producer Operator | I29: Mine only | J29: Kennedy Brothers Construction, | K29: P.O. Box 1608, Jasper, AL 35502 | M29: Appalachia Southern | N29: 3283 | O29: 2 | P29: 1897 | Q29: =IFERROR(LEFT(D29, FIND(VLOOKUP("state_name_split_token", Keys!$B:$C, 2, FALSE), D29)-1), D29) -> Alabama | R29: =IF(OR(Q29=VLOOKUP("lignite_state_1", Keys!$B:$C, 2, FALSE),Q29=VLOOKUP("lignite_state_2", Keys!$B:$C, 2, FALSE),Q29=VLOOKUP("lignite_state_3", Keys!$B:$C, 2, FALSE),Q29=VLOOKUP("lignite_state_4", Keys!$B:$C, 2, FALSE)),VLOOKUP("lignite_label", Keys!$B:$C, 2, FALSE),VLOOKUP("hard_coal_label", Keys!$B:$C, 2, FALSE)) -> hard_coal
A30: 2024 | B30: 5000030 | C30: Usibelli | D30: Alaska | E30: Denali | F30: Active | G30: Surface | H30: Independent Producer Operator | I30: Mine and Preparation Plant | J30: Usibelli Coal Mine Inc | K30: P.O. Box 1000, Healy, AK 99743 | L30: International Brotherhood Of Teamsters, Chauffeurs, Warehouse | M30: Western | N30: 1003565 | O30: 105 | P30: 202813 | Q30: =IFERROR(LEFT(D30, FIND(VLOOKUP("state_name_split_token", Keys!$B:$C, 2, FALSE), D30)-1), D30) -> Alaska | R30: =IF(OR(Q30=VLOOKUP("lignite_state_1", Keys!$B:$C, 2, FALSE),Q30=VLOOKUP("lignite_state_2", Keys!$B:$C, 2, FALSE),Q30=VLOOKUP("lignite_state_3", Keys!$B:$C, 2, FALSE),Q30=VLOOKUP("lignite_state_4", Keys!$B:$C, 2, FALSE)),VLOOKUP("lignite_label", Keys!$B:$C, 2, FALSE),VLOOKUP("hard_coal_label", Keys!$B:$C, 2, FALSE)) -> hard_coal
A31: 2024 | B31: 503672 | C31: West Elk Mine | D31: Colorado | E31: Gunnison | F31: Active | G31: Underground | H31: Operating Subsidiary | I31: Mine and Preparation Plant | J31: Mountain Coal Company, L.L.C. | K31: 5174 Highway 133, Somerset, CO 81434 | M31: Uinta Region | N31: 3705019 | O31: 323 | P31: 652830 | Q31: =IFERROR(LEFT(D31, FIND(VLOOKUP("state_name_split_token", Keys!$B:$C, 2, FALSE), D31)-1), D31) -> Colorado | R31: =IF(OR(Q31=VLOOKUP("lignite_state_1", Keys!$B:$C, 2, FALSE),Q31=VLOOKUP("lignite_state_2", Keys!$B:$C, 2, FALSE),Q31=VLOOKUP("lignite_state_3", Keys!$B:$C, 2, FALSE),Q31=VLOOKUP("lignite_state_4", Keys!$B:$C, 2, FALSE)),VLOOKUP("lignite_label", Keys!$B:$C, 2, FALSE),VLOOKUP("hard_coal_label", Keys!$B:$C, 2, FALSE)) -> hard_coal
A32: 2024 | B32: 504864 | C32: King Ii | D32: Colorado | E32: La Plata | F32: Active | G32: Underground | H32: Independent Producer Operator | I32: Mine only | J32: Gcc Energy Llc | K32: 6473 County Road 120, Hesperus, CO 81326 | M32: Western | N32: 582342 | O32: 104 | P32: 167632 | Q32: =IFERROR(LEFT(D32, FIND(VLOOKUP("state_name_split_token", Keys!$B:$C, 2, FALSE), D32)-1), D32) -> Colorado | R32: =IF(OR(Q32=VLOOKUP("lignite_state_1", Keys!$B:$C, 2, FALSE),Q32=VLOOKUP("lignite_state_2", Keys!$B:$C, 2, FALSE),Q32=VLOOKUP("lignite_state_3", Keys!$B:$C, 2, FALSE),Q32=VLOOKUP("lignite_state_4", Keys!$B:$C, 2, FALSE)),VLOOKUP("lignite_label", Keys!$B:$C, 2, FALSE),VLOOKUP("hard_coal_label", Keys!$B:$C, 2, FALSE)) -> hard_coal
A33: 2024 | B33: 502838 | C33: Trapper Mine | D33: Colorado | E33: Moffat | F33: Active | G33: Surface | H33: Independent Producer Operator | I33: Mine only | J33: Trapper Mining Inc | K33: P.O. Box 187, Craig, CO 81626 | L33: International Union Of Operation Engineers | M33: Uinta Region | N33: 1521960 | O33: 134 | P33: 286955 | Q33: =IFERROR(LEFT(D33, FIND(VLOOKUP("state_name_split_token", Keys!$B:$C, 2, FALSE), D33)-1), D33) -> Colorado | R33: =IF(OR(Q33=VLOOKUP("lignite_state_1", Keys!$B:$C, 2, FALSE),Q33=VLOOKUP("lignite_state_2", Keys!$B:$C, 2, FALSE),Q33=VLOOKUP("lignite_state_3", Keys!$B:$C, 2, FALSE),Q33=VLOOKUP("lignite_state_4", Keys!$B:$C, 2, FALSE)),VLOOKUP("lignite_label", Keys!$B:$C, 2, FALSE),VLOOKUP("hard_coal_label", Keys!$B:$C, 2, FALSE)) -> hard_coal
A34: 2024 | B34: 502962 | C34: Colowyo Mine | D34: Colorado | E34: Moffat | F34: Active | G34: Surface | H34: Operating Subsidiary | I34: Mine and Preparation Plant | J34: Colowyo Coal Company L P | K34: 5731 State Highway 13, Meeker, CO 81625 | M34: Uinta Region | N34: 1713919 | O34: 184 | P34: 305379 | Q34: =IFERROR(LEFT(D34, FIND(VLOOKUP("state_name_split_token", Keys!$B:$C, 2, FALSE), D34)-1), D34) -> Colorado | R34: =IF(OR(Q34=VLOOKUP("lignite_state_1", Keys!$B:$C, 2, FALSE),Q34=VLOOKUP("lignite_state_2", Keys!$B:$C, 2, FALSE),Q34=VLOOKUP("lignite_state_3", Keys!$B:$C, 2, FALSE),Q34=VLOOKUP("lignite_state_4", Keys!$B:$C, 2, FALSE)),VLOOKUP("lignite_label", Keys!$B:$C, 2, FALSE),VLOOKUP("hard_coal_label", Keys!$B:$C, 2, FALSE)) -> hard_coal
A35: 2024 | B35: 1202445 | C35: Addcar System 40 Hwm Serial No | D35: Colorado | E35: Moffat | F35: Active | G35: Surface | H35: Independent Producer Operator | I35: Mine only | J35: Mega Highwall Mining Llc | K35: 12081 Virginia Blvd., Ashland, KY 40112 | M35: Uinta Region | N35: 479996 | O35: 17 | P35: 44973 | Q35: =IFERROR(LEFT(D35, FIND(VLOOKUP("state_name_split_token", Keys!$B:$C, 2, FALSE), D35)-1), D35) -> Colorado | R35: =IF(OR(Q35=VLOOKUP("lignite_state_1", Keys!$B:$C, 2, FALSE),Q35=VLOOKUP("lignite_state_2", Keys!$B:$C, 2, FALSE),Q35=VLOOKUP("lignite_state_3", Keys!$B:$C, 2, FALSE),Q35=VLOOKUP("lignite_state_4", Keys!$B:$C, 2, FALSE)),VLOOKUP("lignite_label", Keys!$B:$C, 2, FALSE),VLOOKUP("hard_coal_label", Keys!$B:$C, 2, FALSE)) -> hard_coal
A36: 2024 | B36: 4003376 | C36: Addcar System 16 | D36: Colorado | E36: Moffat | F36: Active | G36: Surface | H36: Independent Producer Operator | I36: Mine only | J36: Mega Highwall Mining Llc | K36: 12081 Va. Blvd, Ashland, KY 41102 | M36: Uinta Region | N36: 1485020 | O36: 22 | P36: 56069 | Q36: =IFERROR(LEFT(D36, FIND(VLOOKUP("state_name_split_token", Keys!$B:$C, 2, FALSE), D36)-1), D36) -> Colorado | R36: =IF(OR(Q36=VLOOKUP("lignite_state_1", Keys!$B:$C, 2, FALSE),Q36=VLOOKUP("lignite_state_2", Keys!$B:$C, 2, FALSE),Q36=VLOOKUP("lignite_state_3", Keys!$B:$C, 2, FALSE),Q36=VLOOKUP("lignite_state_4", Keys!$B:$C, 2, FALSE)),VLOOKUP("lignite_label", Keys!$B:$C, 2, FALSE),VLOOKUP("hard_coal_label", Keys!$B:$C, 2, FALSE)) -> hard_coal
A37: 2024 | B37: 503505 | C37: Deserado Mine | D37: Colorado | E37: Rio Blanco | F37: Active | G37: Underground | H37: Operating Subsidiary | I37: Mine and Preparation Plant | J37: Blue Mountain Energy Inc | K37: 3607 County Road #65, Rangely, CO 81648 | L37: United Mine Workers Of America | M37: Uinta Region | N37: 1907363 | O37: 167 | P37: 318930 | Q37: =IFERROR(LEFT(D37, FIND(VLOOKUP("state_name_split_token", Keys!$B:$C, 2, FALSE), D37)-1), D37) -> Colorado | R37: =IF(OR(Q37=VLOOKUP("lignite_state_1", Keys!$B:$C, 2, FALSE),Q37=VLOOKUP("lignite_state_2", Keys!$B:$C, 2, FALSE),Q37=VLOOKUP("lignite_state_3", Keys!$B:$C, 2, FALSE),Q37=VLOOKUP("lignite_state_4", Keys!$B:$C, 2, FALSE)),VLOOKUP("lignite_label", Keys!$B:$C, 2, FALSE),VLOOKUP("hard_coal_label", Keys!$B:$C, 2, FALSE)) -> hard_coal
A38: 2024 | B38: 503836 | C38: Foidel Creek Mine | D38: Colorado | E38: Routt | F38: Active | G38: Underground | H38: Operating Subsidiary | I38: Mine and Preparation Plant | J38: Peabody Twentymile Mining Llc | K38: 29515 Routt Cnty Rd#27, Oak Creek, CO 80467 | M38: Uinta Region | N38: 995706 | O38: 215 | P38: 618434 | Q38: =IFERROR(LEFT(D38, FIND(VLOOKUP("state_name_split_token", Keys!$B:$C, 2, FALSE), D38)-1), D38) -> Colorado | R38: =IF(OR(Q38=VLOOKUP("lignite_state_1", Keys!$B:$C, 2, FALSE),Q38=VLOOKUP("lignite_state_2", Keys!$B:$C, 2, FALSE),Q38=VLOOKUP("lignite_state_3", Keys!$B:$C, 2, FALSE),Q38=VLOOKUP("lignite_state_4", Keys!$B:$C, 2, FALSE)),VLOOKUP("lignite_label", Keys!$B:$C, 2, FALSE),VLOOKUP("hard_coal_label", Keys!$B:$C, 2, FALSE)) -> hard_coal
A39: 2024 | B39: 1103189 | C39: Mc#1 Mine | D39: Illinois | E39: Franklin | F39: Active | G39: Underground | H39: Independent Producer Operator | I39: Mine and Preparation Plant | J39: M-Class Mining Llc | K39: 11351 N. Thompsonville Rd., Macedonia, IL 62860 | M39: Illinois Basin | N39: 6216015 | O39: 276 | P39: 636906 | Q39: =IFERROR(LEFT(D39, FIND(VLOOKUP("state_name_split_token", Keys!$B:$C, 2, FALSE), D39)-1), D39) -> Illinois | R39: =IF(OR(Q39=VLOOKUP("lignite_state_1", Keys!$B:$C, 2, FALSE),Q39=VLOOKUP("lignite_state_2", Keys!$B:$C, 2, FALSE),Q39=VLOOKUP("lignite_state_3", Keys!$B:$C, 2, FALSE),Q39=VLOOKUP("lignite_state_4", Keys!$B:$C, 2, FALSE)),VLOOKUP("lignite_label", Keys!$B:$C, 2, FALSE),VLOOKUP("hard_coal_label", Keys!$B:$C, 2, FALSE)) -> hard_coal
A40: 2024 | B40: 1103203 | C40: Mine No. 1 | D40: Illinois | E40: Hamilton | F40: Active | G40: Underground | H40: Operating Subsidiary | I40: Mine only | J40: Hamilton County Coal, Llc | K40: 18033 County Road 500 East, Dahlgren, IL 62828 | M40: Illinois Basin | N40: 4773185 | O40: 373 | P40: 863129 | Q40: =IFERROR(LEFT(D40, FIND(VLOOKUP("state_name_split_token", Keys!$B:$C, 2, FALSE), D40)-1), D40) -> Illinois | R40: =IF(OR(Q40=VLOOKUP("lignite_state_1", Keys!$B:$C, 2, FALSE),Q40=VLOOKUP("lignite_state_2", Keys!$B:$C, 2, FALSE),Q40=VLOOKUP("lignite_state_3", Keys!$B:$C, 2, FALSE),Q40=VLOOKUP("lignite_state_4", Keys!$B:$C, 2, FALSE)),VLOOKUP("lignite_label", Keys!$B:$C, 2, FALSE),VLOOKUP("hard_coal_label", Keys!$B:$C, 2, FALSE)) -> hard_coal
A41: 2024 | B41: 1103242 | C41: Hamilton County Coal Processin | D41: Illinois | E41: Hamilton | F41: Active | G41: Underground | H41: Independent Producer Operator | I41: Preparation Plant | J41: Hamilton County Coal, Llc | K41: 18031 County Rd 500 East, Dahlgren, IL 62828 | M41: Illinois Basin | N41: 0 | O41: 41 | P41: 86195 | Q41: =IFERROR(LEFT(D41, FIND(VLOOKUP("state_name_split_token", Keys!$B:$C, 2, FALSE), D41)-1), D41) -> Illinois | R41: =IF(OR(Q41=VLOOKUP("lignite_state_1", Keys!$B:$C, 2, FALSE),Q41=VLOOKUP("lignite_state_2", Keys!$B:$C, 2, FALSE),Q41=VLOOKUP("lignite_state_3", Keys!$B:$C, 2, FALSE),Q41=VLOOKUP("lignite_state_4", Keys!$B:$C, 2, FALSE)),VLOOKUP("lignite_label", Keys!$B:$C, 2, FALSE),VLOOKUP("hard_coal_label", Keys!$B:$C, 2, FALSE)) -> hard_coal
...

Sheet EIA923_Page1_coal_raw
A1: U.S. Department of Energy, The Energy Information Administration (EIA)
A2: EIA-923 Monthly Generation and Fuel Consumption Time Series File, 2024 Final Data
A3: Sources: EIA-923 and EIA-860 Reports
T5: Total Quantity Consumed In Physical Units (Consumed For Electric Generation And Useful Thermal Output) | AF5: Quantity Consumed In Physical Units For Electric Generation | AR5: Heat Content Of Fuels (MMBtu Per Unit) | BD5: Total Fuel Consumed (MMBtu) | BP5: Quantity Consumed For Electricity (MMBtu) | CB5: Electricity Net Generation (MWh) | CN5: Year-To-Date
A6: Plant Id | B6: Combined Heat And Power Plant | C6: Nuclear Unit Id | D6: Plant Name | E6: Operator Name | F6: Operator Id | G6: Plant State | H6: Census Region | I6: NERC Region | J6: Reserved | K6: NAICS Code | L6: EIA Sector Number | M6: Sector Name | N6: Reported Prime Mover | O6: Reported Fuel Type Code | P6: MER Fuel Type Code | Q6: Balancing Authority Code | R6: Respondent Frequency | S6: Physical Unit Label | T6: Quantity January | U6: Quantity February | V6: Quantity March | W6: Quantity April | X6: Quantity May | Y6: Quantity June | Z6: Quantity July | AA6: Quantity August | AB6: Quantity September | AC6: Quantity October | AD6: Quantity November | AE6: Quantity December | AF6: Elec_Quantity January | AG6: Elec_Quantity February | AH6: Elec_Quantity March | AI6: Elec_Quantity April | AJ6: Elec_Quantity May | AK6: Elec_Quantity June | AL6: Elec_Quantity July | AM6: Elec_Quantity August | AN6: Elec_Quantity September | AO6: Elec_Quantity October | AP6: Elec_Quantity November | AQ6: Elec_Quantity December | AR6: MMBtuPer_Unit January | AS6: MMBtuPer_Unit February | AT6: MMBtuPer_Unit March | AU6: MMBtuPer_Unit April | AV6: MMBtuPer_Unit May | AW6: MMBtuPer_Unit June | AX6: MMBtuPer_Unit July | AY6: MMBtuPer_Unit August | AZ6: MMBtuPer_Unit September | BA6: MMBtuPer_Unit October | BB6: MMBtuPer_Unit November | BC6: MMBtuPer_Unit December | BD6: Tot_MMBtu January | BE6: Tot_MMBtu February | BF6: Tot_MMBtu March | BG6: Tot_MMBtu April | BH6: Tot_MMBtu May | BI6: Tot_MMBtu June | BJ6: Tot_MMBtu July | BK6: Tot_MMBtu August | BL6: Tot_MMBtu September | BM6: Tot_MMBtu October | BN6: Tot_MMBtu November | BO6: Tot_MMBtu December | BP6: Elec_MMBtu January | BQ6: Elec_MMBtu February | BR6: Elec_MMBtu March | BS6: Elec_MMBtu April | BT6: Elec_MMBtu May | BU6: Elec_MMBtu June | BV6: Elec_MMBtu July | BW6: Elec_MMBtu August | BX6: Elec_MMBtu September | BY6: Elec_MMBtu October | BZ6: Elec_MMBtu November | CA6: Elec_MMBtu December | CB6: Netgen January | CC6: Netgen February | CD6: Netgen March | CE6: Netgen April | CF6: Netgen May | CG6: Netgen June | CH6: Netgen July | CI6: Netgen August | CJ6: Netgen September | CK6: Netgen October | CL6: Netgen November | CM6: Netgen December | CN6: Total Fuel Consumption Quantity | CO6: Electric Fuel Consumption Quantity | CP6: Total Fuel Consumption MMBtu | CQ6: Elec Fuel Consumption MMBtu | CR6: Net Generation (Megawatthours) | CS6: YEAR | CT6: helper: state_name | CU6: helper: rank
A7: 3 | B7: N | C7: . | D7: Barry | E7: Alabama Power Co | F7: 195 | G7: AL | H7: ESC | I7: SERC | K7: 22 | L7: 1 | M7: Electric Utility | N7: ST | O7: BIT | P7: COL | Q7: SOCO | R7: M | S7: short tons | T7: 44058 | U7: 0 | V7: 0 | W7: 47328 | X7: 0 | Y7: 44248 | Z7: 68612 | AA7: 0 | AB7: 15734 | AC7: 166757 | AD7: 8885 | AE7: 0 | AF7: 44058 | AG7: 0 | AH7: 0 | AI7: 47328 | AJ7: 0 | AK7: 44248 | AL7: 68612 | AM7: 0 | AN7: 15734 | AO7: 166757 | AP7: 8885 | AQ7: 0 | AR7: 19.908 | AS7: 0 | AT7: 0 | AU7: 19.908 | AV7: 0 | AW7: 19.908 | AX7: 19.908 | AY7: 0 | AZ7: 19.243 | BA7: 19.603 | BB7: 19.485 | BC7: 0 | BD7: 877107 | BE7: 0 | BF7: 0 | BG7: 942206 | BH7: 0 | BI7: 880889 | BJ7: 1365928 | BK7: 0 | BL7: 302769 | BM7: 3268937 | BN7: 173124 | BO7: 0 | BP7: 877107 | BQ7: 0 | BR7: 0 | BS7: 942206 | BT7: 0 | BU7: 880889 | BV7: 1365928 | BW7: 0 | BX7: 302769 | BY7: 3268937 | BZ7: 173124 | CA7: 0 | CB7: 74699.628 | CC7: -4538.357 | CD7: 0 | CE7: 83997.467 | CF7: 0 | CG7: 75098.285 | CH7: 114680.23 | CI7: 0 | CJ7: 20325.048 | CK7: 322168.46 | CL7: 11097.797 | CM7: 0 | CN7: 395622 | CO7: 395622 | CP7: 7810960 | CQ7: 7810960 | CR7: 697528.56 | CS7: 2024 | CT7: =IFERROR(INDEX(Geography!C:C, MATCH(G7, Geography!B:B, 0)), G7) -> Alabama | CU7: =IF(O7=VLOOKUP("eia923_lignite_fuel_code", Keys!$B:$C, 2, FALSE), VLOOKUP("lignite_label", Keys!$B:$C, 2, FALSE),VLOOKUP("hard_coal_label", Keys!$B:$C, 2, FALSE)) -> hard_coal
A8: 3 | B8: N | C8: . | D8: Barry | E8: Alabama Power Co | F8: 195 | G8: AL | H8: ESC | I8: SERC | K8: 22 | L8: 1 | M8: Electric Utility | N8: ST | O8: SUB | P8: COL | Q8: SOCO | R8: M | S8: short tons | T8: 0 | U8: 0 | V8: 0 | W8: 0 | X8: 0 | Y8: 0 | Z8: 0 | AA8: 0 | AB8: 0 | AC8: 0 | AD8: 0 | AE8: 0 | AF8: 0 | AG8: 0 | AH8: 0 | AI8: 0 | AJ8: 0 | AK8: 0 | AL8: 0 | AM8: 0 | AN8: 0 | AO8: 0 | AP8: 0 | AQ8: 0 | AR8: 0 | AS8: 0 | AT8: 0 | AU8: 0 | AV8: 0 | AW8: 0 | AX8: 0 | AY8: 0 | AZ8: 0 | BA8: 0 | BB8: 0 | BC8: 0 | BD8: 0 | BE8: 0 | BF8: 0 | BG8: 0 | BH8: 0 | BI8: 0 | BJ8: 0 | BK8: 0 | BL8: 0 | BM8: 0 | BN8: 0 | BO8: 0 | BP8: 0 | BQ8: 0 | BR8: 0 | BS8: 0 | BT8: 0 | BU8: 0 | BV8: 0 | BW8: 0 | BX8: 0 | BY8: 0 | BZ8: 0 | CA8: 0 | CB8: 0 | CC8: 0 | CD8: 0 | CE8: 0 | CF8: 0 | CG8: 0 | CH8: 0 | CI8: 0 | CJ8: 0 | CK8: 0 | CL8: 0 | CM8: 0 | CN8: 0 | CO8: 0 | CP8: 0 | CQ8: 0 | CR8: 0 | CS8: 2024 | CT8: =IFERROR(INDEX(Geography!C:C, MATCH(G8, Geography!B:B, 0)), G8) -> Alabama | CU8: =IF(O8=VLOOKUP("eia923_lignite_fuel_code", Keys!$B:$C, 2, FALSE), VLOOKUP("lignite_label", Keys!$B:$C, 2, FALSE),VLOOKUP("hard_coal_label", Keys!$B:$C, 2, FALSE)) -> hard_coal
