Workbook

Sheet About
A1: MPPC Minimum Power Plant Capacity | B1: Missouri | C1: 46239 | F1: Alabama | G1: AL
B2: =LOOKUP(B1,F1:G50,G1:G50) -> MO | F2: Alaska | G2: AK
A3: Source: | B3: All Except Offshore Wind | F3: Arizona | G3: AZ
B4: Energy Information Administration | F4: Arkansas | G4: AR
B5: 2021 | F5: California | G5: CA
B6: Form 860 | F6: Colorado | G6: CO
B7: http://www.eia.gov/electricity/data/eia860/ | F7: Connecticut | G7: CT
B8: Generators file, "Operable" tab | F8: Delaware | G8: DE
F9: Florida | G9: FL
B10: Offshore Wind | F10: Georgia | G10: GA
B11: Department of Energy | F11: Hawaii | G11: HI
B12: 2015 | F12: Idaho | G12: ID
B13: 2014–2015 Offshore Wind Technologies Market Report Data Tables | F13: Illinois | G13: IL
B14: https://energy.gov/sites/prod/files/2015/09/f26/2014-2015-Offshore-Wind-Technologies-Market-Report-data-tables-9-25_0.xlsx | F14: Indiana | G14: IN
B15: Figure 12 | F15: Iowa | G15: IA
F16: Kansas | G16: KS
B17: Small Modular Reactors | F17: Kentucky | G17: KY
B18: Department of Energy | F18: Louisiana | G18: LA
B19: Advanced Small Modular Reactors (SMRs) | F19: Maine | G19: ME
B20: https://www.energy.gov/ne/advanced-small-modular-reactors-smrs | F20: Maryland | G20: MD
B21: first paragraph | F21: Massachusetts | G21: MA
F22: Michigan | G22: MI
A23: Notes | F23: Minnesota | G23: MN
A24: We use the twentieth percentile of all operable plants in the U.S. | F24: Mississippi | G24: MS
A25: built since 1975 as the minimum capacity of a new power plant. | F25: Missouri | G25: MO
F26: Montana | G26: MT
A27: For offshore wind, we use the twentieth percnetile of all global | F27: Nebraska | G27: NE
A28: plants. | F28: Nevada | G28: NV
F29: New Hampshire | G29: NH
A30: For hard coal and lignite coal we use a single value for all coal | F30: New Jersey | G30: NJ
A31: plants in the U.S. | F31: New Mexico | G31: NM
F32: New York | G32: NY
A33: For SMRs, we use a value of 20 (DOE reports SMRs as envisioned to | F33: North Carolina | G33: NC
A34: vary in size from tens of MW to hundreds of MW). | F34: North Dakota | G34: ND
F35: Ohio | G35: OH
A36: STATES | F36: Oklahoma | G36: OK
A37: for state values, hold constant at minimum increments across states | F37: Oregon | G37: OR
F38: Pennsylvania | G38: PA
F39: Rhode Island | G39: RI
F40: South Carolina | G40: SC
...

Sheet Plant Size Breakdown
D1: Percentile
D2: 0.2
A3: Technology | B3: Model Energy Source | C3: Minimum | D3: Xth Percentile | E3: Average
A4: Conventional Hydroelectric | B4: hydro | C4: {=MIN(IF(Pivot!$A:$A='Plant Size Breakdown'!A4,Pivot!$D:$D))} -> 0.2 | D4: {=PERCENTILE(IF(Pivot!$A:$A='Plant Size Breakdown'!A4,Pivot!$D:$D),$D$2)} -> 1.44 | E4: {=AVERAGE(IF(Pivot!$A:$A='Plant Size Breakdown'!A4,Pivot!$D:$D))} -> 17.062226
A5: Conventional Steam Coal | B5: coal | C5: {=MIN(IF(Pivot!$A:$A='Plant Size Breakdown'!A5,Pivot!$D:$D))} -> 5 | D5: {=PERCENTILE(IF(Pivot!$A:$A='Plant Size Breakdown'!A5,Pivot!$D:$D),$D$2)} -> 279.72 | E5: {=AVERAGE(IF(Pivot!$A:$A='Plant Size Breakdown'!A5,Pivot!$D:$D))} -> 550.94942
A6: Geothermal | B6: geothermal | C6: {=MIN(IF(Pivot!$A:$A='Plant Size Breakdown'!A6,Pivot!$D:$D))} -> 2.4 | D6: {=PERCENTILE(IF(Pivot!$A:$A='Plant Size Breakdown'!A6,Pivot!$D:$D),$D$2)} -> 12.6 | E6: {=AVERAGE(IF(Pivot!$A:$A='Plant Size Breakdown'!A6,Pivot!$D:$D))} -> 39.795181
A7: Municipal Solid Waste | B7: biomass | C7: {=MIN(IF(Pivot!$A:$A='Plant Size Breakdown'!A7,Pivot!$D:$D))} -> 9.4 | D7: {=PERCENTILE(IF(Pivot!$A:$A='Plant Size Breakdown'!A7,Pivot!$D:$D),$D$2)} -> 16.64 | E7: {=AVERAGE(IF(Pivot!$A:$A='Plant Size Breakdown'!A7,Pivot!$D:$D))} -> 42.119048
A8: Natural Gas Fired Combined Cycle | B8: natural gas combined cycle | C8: {=MIN(IF(Pivot!$A:$A='Plant Size Breakdown'!A8,Pivot!$D:$D))} -> 6 | D8: {=PERCENTILE(IF(Pivot!$A:$A='Plant Size Breakdown'!A8,Pivot!$D:$D),$D$2)} -> 162.56 | E8: {=AVERAGE(IF(Pivot!$A:$A='Plant Size Breakdown'!A8,Pivot!$D:$D))} -> 533.42755
A9: Natural Gas Steam Turbine | B9: natural gas steam turbine | C9: {=MIN(IF(Pivot!$A:$A='Plant Size Breakdown'!A9,Pivot!$D:$D))} -> 6 | D9: {=PERCENTILE(IF(Pivot!$A:$A='Plant Size Breakdown'!A9,Pivot!$D:$D),$D$2)} -> 21.2 | E9: {=AVERAGE(IF(Pivot!$A:$A='Plant Size Breakdown'!A9,Pivot!$D:$D))} -> 259.5375
A10: Natural Gas Fired Combustion Turbine | B10: natural gas peaker | C10: {=MIN(IF(Pivot!$A:$A='Plant Size Breakdown'!A10,Pivot!$D:$D))} -> 2 | D10: {=PERCENTILE(IF(Pivot!$A:$A='Plant Size Breakdown'!A10,Pivot!$D:$D),$D$2)} -> 49.8 | E10: {=AVERAGE(IF(Pivot!$A:$A='Plant Size Breakdown'!A10,Pivot!$D:$D))} -> 207.05203
A11: Nuclear | B11: nuclear | C11: {=MIN(IF(Pivot!$A:$A='Plant Size Breakdown'!A11,Pivot!$D:$D))} -> 888.2 | D11: {=PERCENTILE(IF(Pivot!$A:$A='Plant Size Breakdown'!A11,Pivot!$D:$D),$D$2)} -> 1138.5 | E11: {=AVERAGE(IF(Pivot!$A:$A='Plant Size Breakdown'!A11,Pivot!$D:$D))} -> 1277.3787
A12: Onshore Wind Turbine | B12: wind | C12: {=MIN(IF(Pivot!$A:$A='Plant Size Breakdown'!A12,Pivot!$D:$D))} -> 0.1 | D12: {=PERCENTILE(IF(Pivot!$A:$A='Plant Size Breakdown'!A12,Pivot!$D:$D),$D$2)} -> 6 | E12: {=AVERAGE(IF(Pivot!$A:$A='Plant Size Breakdown'!A12,Pivot!$D:$D))} -> 89.713853
A13: Other Waste Biomass | B13: biomass | C13: {=MIN(IF(Pivot!$A:$A='Plant Size Breakdown'!A13,Pivot!$D:$D))} -> 1 | D13: {=PERCENTILE(IF(Pivot!$A:$A='Plant Size Breakdown'!A13,Pivot!$D:$D),$D$2)} -> 1 | E13: {=AVERAGE(IF(Pivot!$A:$A='Plant Size Breakdown'!A13,Pivot!$D:$D))} -> 7.0153846
A14: Petroleum Liquids | B14: petroleum | C14: {=MIN(IF(Pivot!$A:$A='Plant Size Breakdown'!A14,Pivot!$D:$D))} -> 0.1 | D14: {=PERCENTILE(IF(Pivot!$A:$A='Plant Size Breakdown'!A14,Pivot!$D:$D),$D$2)} -> 1.1 | E14: {=AVERAGE(IF(Pivot!$A:$A='Plant Size Breakdown'!A14,Pivot!$D:$D))} -> 8.7733179
A15: Solar Photovoltaic | B15: solar pv | C15: {=MIN(IF(Pivot!$A:$A='Plant Size Breakdown'!A15,Pivot!$D:$D))} -> 0.1 | D15: {=PERCENTILE(IF(Pivot!$A:$A='Plant Size Breakdown'!A15,Pivot!$D:$D),$D$2)} -> 1.5 | E15: {=AVERAGE(IF(Pivot!$A:$A='Plant Size Breakdown'!A15,Pivot!$D:$D))} -> 11.236599
... A18: Wood/Wood Waste Biomass | B18: biomass | C18: {=MIN(IF(Pivot!$A:$A='Plant Size Breakdown'!A18,Pivot!$D:$D))} -> 3 | D18: {=PERCENTILE(IF(Pivot!$A:$A='Plant Size Breakdown'!A18,Pivot!$D:$D),$D$2)} -> 18 | E18: {=AVERAGE(IF(Pivot!$A:$A='Plant Size Breakdown'!A18,Pivot!$D:$D))} -> 36.558929

Sheet Pivot
A2: Sector Name | B2: (Multiple Items)
A4: Technology | B4: Plant Name | C4: Operating Year | D4: Sum of Nameplate Capacity (MW)
A5: Conventional Hydroelectric | B5: 45 Mile Hydroelectric Project | C5: 2015 | D5: 3
A6: Conventional Hydroelectric | B6: Abiquiu Dam | C6: 1989 | D6: 12.6
A7: Conventional Hydroelectric | B7: Abiquiu Dam | C7: 2011 | D7: 3
A8: Conventional Hydroelectric | B8: Ada Dam | C8: 1984 | D8: 1.4
A9: Conventional Hydroelectric | B9: Alamo | C9: 1986 | D9: 19.6
A10: Conventional Hydroelectric | B10: Alice Falls Hydro Project | C10: 1991 | D10: 2.1
A11: Conventional Hydroelectric | B11: Allegheny Hydro No 8 | C11: 1990 | D11: 13.6
A12: Conventional Hydroelectric | B12: Allegheny Hydro No 9 | C12: 1990 | D12: 17.8
A13: Conventional Hydroelectric | B13: Allegheny No 6 Hydro Station | C13: 1988 | D13: 9.2
A14: Conventional Hydroelectric | B14: Allegheny No. 5 Hydro Station | C14: 1988 | D14: 9.2
A15: Conventional Hydroelectric | B15: Amistad Dam & Power | C15: 1983 | D15: 66
A16: Conventional Hydroelectric | B16: Anson Abenaki Hydros | C16: 1980 | D16: 2.7
... A7342: Wood/Wood Waste Biomass | B7342: Stored Solar Fitchburg, LLC | C7342: 1992 | D7342: 18

Sheet MPPC
B1: Minimum Capacity (MW)
A2: hard coal | B2: 50
A3: natural gas steam turbine | B3: 50
A4: natural gas combined cycle | B4: 50
A5: nuclear | B5: 500
A6: hydro | B6: 1
A7: onshore wind | B7: 1
A8: solar PV | B8: 1
A9: solar thermal | B9: 50
A10: biomass | B10: 1
A11: geothermal | B11: 50
A12: petroleum | B12: 50
A13: natural gas peaker | B13: 50
... A25: hydrogen combined cycle | B25: 100
